<?xml version="1.0" ?>
<!-- =================================================================================== -->
<!-- |    This document was autogenerated by xacro from galbot_one_golf.xacro          | -->
<!-- |    EDITING THIS FILE BY HAND IS NOT RECOMMENDED                                 | -->
<!-- =================================================================================== -->
<!-- 
#####################################################################################
#
# Copyright (c) 2023-2025 Galbot, Inc. All Rights Reserved.
#
# This software contains confidential and proprietary information of Galbot, Inc.
# ("Confidential Information"). You shall not disclose such Confidential Information
# and shall use it only in accordance with the terms of the license agreement you
# entered into with Galbot, Inc.
#
# UNAUTHORIZED COPYING, USE, OR DISTRIBUTION OF THIS SOFTWARE, OR ANY PORTION OR
# DERIVATIVE THEREOF, IS STRICTLY PROHIBITED. IF YOU HAVE RECEIVED THIS SOFTWARE IN
# ERROR, PLEASE NOTIFY GALBOT, INC. IMMEDIATELY AND DELETE IT FROM YOUR SYSTEM.
#
#####################################################################################
#
# Description: XACRO file for galbot one golf.
# Maintainer: Herman Ye, Yuhao Zeng, Fei Shi@Galbot
#
#####################################################################################
-->
<robot name="galbot_one_golf">
  <!-- ROBOT -->
  <!-- Robot Base Link -->
  <link name="base_link">
    </link>
  <joint name="omni_chassis_joint" type="fixed">
    <origin rpy="0 0 0" xyz="0 0 0"/>
    <parent link="base_link"/>
    <child link="omni_chassis_base_link"/>
  </joint>
  <link name="omni_chassis_base_link">
    <inertial>
      <origin rpy="0 0 0" xyz="0.02644 -0.00449 0.07524"/>
      <mass value="8.04"/>
      <inertia ixx="0.19508898000000002" ixy="0.00306854" ixz="0.01503967" iyy="0.29573702" iyz="-0.00295148" izz="0.3313144"/>
    </inertial>
    <visual>
      <origin rpy="0 0 0" xyz="0 0 0"/>
      <geometry>
        <mesh filename="meshes/visual/chassis/omni_chassis_base_link/obj/omni_chassis_base_link.obj"/>
      </geometry>
    </visual>
    <collision>
      <origin rpy="0 0 0" xyz="0 0 0"/>
      <geometry>
        <mesh filename="meshes/collision/chassis/omni_chassis_base_link/convex_hull/omni_chassis_base_link_convex_hull.stl"/>
      </geometry>
    </collision>
  </link>
  <link name="omni_chassis_leg_mount_link">
    <inertial>
      <origin rpy="0 0 0" xyz="0 0 0"/>
      <mass value="0"/>
      <inertia ixx="0" ixy="0" ixz="0" iyy="0" iyz="0" izz="0"/>
    </inertial>
  </link>
  <joint name="omni_chassis_leg_mount_joint" type="fixed">
    <origin rpy="0 0 0" xyz="0.134 0 0.1325"/>
    <parent link="omni_chassis_base_link"/>
    <child link="omni_chassis_leg_mount_link"/>
    <axis xyz="0 0 0"/>
  </joint>
  <joint name="leg_joint" type="fixed">
    <origin rpy="0 0 0" xyz="0 0 0"/>
    <parent link="omni_chassis_leg_mount_link"/>
    <child link="leg_base_link"/>
  </joint>
  <link name="leg_base_link">
    <inertial>
      <origin rpy="0 0 0" xyz="7.000000000000001e-05 -0.05414 0.0"/>
      <mass value="1.58"/>
      <inertia ixx="0.00797474" ixy="8.35e-06" ixz="2e-08" iyy="0.00248067" iyz="6.9e-07" izz="0.00797203"/>
    </inertial>
  </link>
  <link name="leg_link1">
    <inertial>
      <origin rpy="0 0 0" xyz="0.21883000000000002 0.00219 -0.0046"/>
      <mass value="5.28"/>
      <inertia ixx="0.0245158" ixy="0.003598" ixz="-0.004119" iyy="0.46437793" iyz="2.301e-05" izz="0.46079615"/>
    </inertial>
    <visual>
      <origin rpy="0 0 0" xyz="0 0 0"/>
      <geometry>
        <mesh filename="meshes/visual/leg/leg_link1/obj/leg_link1.obj"/>
      </geometry>
    </visual>
    <collision>
      <origin rpy="0 0 0" xyz="0 0 0"/>
      <geometry>
        <mesh filename="meshes/collision/leg/leg_link1/convex_hull/leg_link1_convex_hull.stl"/>
      </geometry>
    </collision>
  </link>
  <joint name="leg_joint1" type="revolute">
    <origin rpy="1.5707963267948966 -0.385 3.141592653589793" xyz="0 0 0"/>
    <parent link="leg_base_link"/>
    <child link="leg_link1"/>
    <axis xyz="0 0 1"/>
    <limit effort="169" lower="0.0" upper="0.9374" velocity="1"/>
  </joint>
  <link name="leg_link2">
    <inertial>
      <origin rpy="0 0 0" xyz="0.19484 0.0 0.0"/>
      <mass value="3.3"/>
      <inertia ixx="0.04156241" ixy="7.2e-07" ixz="1.559e-05" iyy="0.23231617000000002" iyz="-2.7799999999999996e-06" izz="0.20323657"/>
    </inertial>
    <visual>
      <origin rpy="0 0 0" xyz="0 0 0"/>
      <geometry>
        <mesh filename="meshes/visual/leg/leg_link2/obj/leg_link2.obj"/>
      </geometry>
    </visual>
    <collision>
      <origin rpy="0 0 0" xyz="0 0 0"/>
      <geometry>
        <mesh filename="meshes/collision/leg/leg_link2/convex_hull/leg_link2_convex_hull.stl"/>
      </geometry>
    </collision>
  </link>
  <joint name="leg_joint2" type="revolute">
    <origin rpy="3.141592653589793 0 2.7566" xyz="0.45 0 0"/>
    <parent link="leg_link1"/>
    <child link="leg_link2"/>
    <axis xyz="0 0 1"/>
    <limit effort="169" lower="0.0" upper="2.5847" velocity="1"/>
  </joint>
  <link name="leg_link3">
    <inertial>
      <origin rpy="0 0 0" xyz="2e-05 0.01881 -0.011"/>
      <mass value="1.76"/>
      <inertia ixx="0.01102444" ixy="1.13e-06" ixz="-1.26e-06" iyy="0.00878281" iyz="1.26e-06" izz="0.0106222"/>
    </inertial>
    <visual>
      <origin rpy="0 0 0" xyz="0 0 0"/>
      <geometry>
        <mesh filename="meshes/visual/leg/leg_link3/obj/leg_link3.obj"/>
      </geometry>
    </visual>
    <collision>
      <origin rpy="0 0 0" xyz="0 0 0"/>
      <geometry>
        <mesh filename="meshes/collision/leg/leg_link3/convex_hull/leg_link3_convex_hull.stl"/>
      </geometry>
    </collision>
  </link>
  <joint name="leg_joint3" type="revolute">
    <origin rpy="3.141592653589793 0 3.141592653589793" xyz="0.39 0 0"/>
    <parent link="leg_link2"/>
    <child link="leg_link3"/>
    <axis xyz="0 0 1"/>
    <limit effort="84" lower="0.0" upper="2.3262" velocity="1"/>
  </joint>
  <link name="leg_link4">
    <inertial>
      <origin rpy="0 0 0" xyz="0.0 -0.0059900000000000005 -0.06877"/>
      <mass value="0.72"/>
      <inertia ixx="0.00580757" ixy="0.0" ixz="0.0" iyy="0.00591483" iyz="4.67e-06" izz="0.0014004900000000001"/>
    </inertial>
    <visual>
      <origin rpy="0 0 0" xyz="0 0 0"/>
      <geometry>
        <mesh filename="meshes/visual/leg/leg_link4/obj/leg_link4.obj"/>
      </geometry>
    </visual>
    <collision>
      <origin rpy="0 0 0" xyz="0 0 0"/>
      <geometry>
        <mesh filename="meshes/collision/leg/leg_link4/convex_hull/leg_link4_convex_hull.stl"/>
      </geometry>
    </collision>
  </link>
  <joint name="leg_joint4" type="revolute">
    <origin rpy="-1.5707963267948966 -1.5707963267948966 0" xyz="0 0.224 0"/>
    <parent link="leg_link3"/>
    <child link="leg_link4"/>
    <axis xyz="0 0 1"/>
    <limit effort="30" lower="-1.5906" upper="1.5906" velocity="1"/>
  </joint>
  <link name="leg_link5">
    <inertial>
      <origin rpy="0 0 0" xyz="0.0 0.032369999999999996 0.03006"/>
      <mass value="0.41"/>
      <inertia ixx="0.00142201" ixy="0.0" ixz="0.0" iyy="0.00132398" iyz="0.00023940999999999999" izz="0.00156199"/>
    </inertial>
    <visual>
      <origin rpy="0 0 0" xyz="0 0 0"/>
      <geometry>
        <mesh filename="meshes/visual/leg/leg_link5/obj/leg_link5.obj"/>
      </geometry>
    </visual>
    <collision>
      <origin rpy="0 0 0" xyz="0 0 0"/>
      <geometry>
        <mesh filename="meshes/collision/leg/leg_link5/convex_hull/leg_link5_convex_hull.stl"/>
      </geometry>
    </collision>
  </link>
  <joint name="leg_joint5" type="revolute">
    <origin rpy="1.5707963267948966 0 0" xyz="0 0 0"/>
    <parent link="leg_link4"/>
    <child link="leg_link5"/>
    <axis xyz="0 0 1"/>
    <limit effort="30" lower="-0.1645" upper="0.1645" velocity="1"/>
    <!-- special soft limit for
      leg joint 5 (0.01 radians)-->
  </joint>
  <link name="leg_end_effector_mount_link">
    <inertial>
      <origin rpy="0 0 0" xyz="0 0 0"/>
      <mass value="0"/>
      <inertia ixx="0" ixy="0" ixz="0" iyy="0" iyz="0" izz="0"/>
    </inertial>
  </link>
  <joint name="leg_end_effector_mount_joint" type="fixed">
    <origin rpy="0 0 0" xyz="0 0 0"/>
    <parent link="leg_link5"/>
    <child link="leg_end_effector_mount_link"/>
    <axis xyz="0 0 0"/>
  </joint>
  <joint name="torso_joint" type="fixed">
    <origin rpy="0 0 0" xyz="0 0 0"/>
    <parent link="leg_end_effector_mount_link"/>
    <child link="torso_base_link"/>
  </joint>
  <link name="torso_base_link">
    <inertial>
      <origin rpy="0 0 0" xyz="-4e-05 0.16976 -0.00174"/>
      <mass value="3.3"/>
      <inertia ixx="0.13068739999999998" ixy="-3.799e-05" ixz="2.6e-07" iyy="0.01888968" iyz="-0.00210909" izz="0.13964288"/>
    </inertial>
    <visual>
      <origin rpy="0 0 0" xyz="0 0 0"/>
      <geometry>
        <mesh filename="meshes/visual/torso/torso_base_link/obj/torso_base_link.obj"/>
      </geometry>
    </visual>
    <collision>
      <origin rpy="0 0 0" xyz="0 0 0"/>
      <geometry>
        <mesh filename="meshes/collision/torso/torso_base_link/convex_hull/torso_base_link_convex_hull.stl"/>
      </geometry>
    </collision>
  </link>
  <!-- Left Arm Mount -->
  <link name="torso_left_arm_mount_link">
    <inertial>
      <origin rpy="0 0 0" xyz="0 0 0"/>
      <mass value="0"/>
      <inertia ixx="0" ixy="0" ixz="0" iyy="0" iyz="0" izz="0"/>
    </inertial>
  </link>
  <joint name="torso_left_arm_mount_joint" type="fixed">
    <origin rpy="0 1.5707963267948966 0" xyz="0.20843 0.172 0"/>
    <parent link="torso_base_link"/>
    <child link="torso_left_arm_mount_link"/>
    <axis xyz="0 0 0"/>
  </joint>
  <!-- Right Arm Mount -->
  <link name="torso_right_arm_mount_link">
    <inertial>
      <origin rpy="0 0 0" xyz="0 0 0"/>
      <mass value="0"/>
      <inertia ixx="0" ixy="0" ixz="0" iyy="0" iyz="0" izz="0"/>
    </inertial>
  </link>
  <joint name="torso_right_arm_mount_joint" type="fixed">
    <origin rpy="3.141592653589793 1.5707963267948966 0" xyz="-0.20843 0.172 0"/>
    <parent link="torso_base_link"/>
    <child link="torso_right_arm_mount_link"/>
    <axis xyz="0 0 0"/>
  </joint>
  <!-- Head Mount -->
  <link name="torso_head_mount_link">
    <inertial>
      <origin rpy="0 0 0" xyz="0 0 0"/>
      <mass value="0"/>
      <inertia ixx="0" ixy="0" ixz="0" iyy="0" iyz="0" izz="0"/>
    </inertial>
  </link>
  <joint name="torso_head_mount_joint" type="fixed">
    <origin rpy="-1.5707963267948966 -1.5707963267948966 0" xyz="0 0.37711 0"/>
    <parent link="torso_base_link"/>
    <child link="torso_head_mount_link"/>
    <axis xyz="0 0 0"/>
  </joint>
  <joint name="head_joint" type="fixed">
    <origin rpy="0 0 0" xyz="0 0 0"/>
    <parent link="torso_head_mount_link"/>
    <child link="head_base_link"/>
  </joint>
  <link name="head_base_link">
    <inertial>
      <origin rpy="0 0 0" xyz="0.023809999999999998 0.00032 0.01966"/>
      <mass value="0.48"/>
      <inertia ixx="0.0032910599999999997" ixy="8.32e-06" ixz="0.00044358" iyy="0.00375998" iyz="7.18e-06" izz="0.00221683"/>
    </inertial>
  </link>
  <link name="head_link1">
    <inertial>
      <origin rpy="0 0 0" xyz="-2e-05 0.00709 -0.0559"/>
      <mass value="1.5695"/>
      <inertia ixx="0.0069002956" ixy="0.00000152205" ixz="0.00000313295" iyy="0.00683300359" iyz="0.00001009318" izz="0.00116967635"/>
    </inertial>
    <visual>
      <origin rpy="0 0 0" xyz="0 0 0"/>
      <geometry>
        <mesh filename="meshes/visual/head/head_link1/obj/head_link1.obj"/>
      </geometry>
    </visual>
    <collision>
      <origin rpy="0 0 0" xyz="0 0 0"/>
      <geometry>
        <mesh filename="meshes/collision/head/head_link1/convex_hull/head_link1_convex_hull.stl"/>
      </geometry>
    </collision>
  </link>
  <joint name="head_joint1" type="revolute">
    <origin rpy="0 0 0" xyz="0 0 0"/>
    <parent link="head_base_link"/>
    <child link="head_link1"/>
    <axis xyz="0 0 1"/>
    <limit effort="4" lower="-1.5208" upper="1.5208" velocity="1.5"/>
  </joint>
  <link name="head_link2">
    <inertial>
      <origin rpy="0 0 0" xyz="0.01835 -0.033479999999999996 0.00642"/>
      <mass value="0.81"/>
      <inertia ixx="0.00000399161" ixy="0.00000129825" ixz="0.00000000392" iyy="0.00000372602" iyz="0.00000000775" izz="0.00000553062"/>
    </inertial>
    <visual>
      <origin rpy="0 0 0" xyz="0 0 0"/>
      <geometry>
        <mesh filename="meshes/visual/head/head_link2/obj/head_link2.obj"/>
      </geometry>
    </visual>
    <collision>
      <origin rpy="0 0 0" xyz="0 0 0"/>
      <geometry>
        <mesh filename="meshes/collision/head/head_link2/convex_hull/head_link2_convex_hull.stl"/>
      </geometry>
    </collision>
  </link>
  <joint name="head_joint2" type="revolute">
    <origin rpy="-1.5707963267948966 0 0" xyz="0 0 0"/>
    <parent link="head_link1"/>
    <child link="head_link2"/>
    <axis xyz="0 0 1"/>
    <!-- Soft limit 0.03 radians lower="-0.2443461" upper="0.5235988" -->
    <limit effort="4" lower="-0.2143461" upper="0.4935988" velocity="1.5"/>
  </joint>
  <link name="head_end_effector_mount_link">
    <inertial>
      <origin rpy="0 0 0" xyz="0 0 0"/>
      <mass value="0"/>
      <inertia ixx="0" ixy="0" ixz="0" iyy="0" iyz="0" izz="0"/>
    </inertial>
  </link>
  <joint name="head_end_effector_mount_joint" type="fixed">
    <origin rpy="0 0 0" xyz="0 0 0"/>
    <parent link="head_link2"/>
    <child link="head_end_effector_mount_link"/>
    <axis xyz="0 0 0"/>
  </joint>
  <joint name="right_arm_joint" type="fixed">
    <origin rpy="0 0 0" xyz="0 0 0"/>
    <parent link="torso_right_arm_mount_link"/>
    <child link="right_arm_base_link"/>
  </joint>
  <link name="right_arm_base_link">
    <inertial>
      <origin rpy="0 0 0" xyz="0.0 0.0 -0.10506"/>
      <mass value="0.92"/>
      <inertia ixx="0.01075595" ixy="9e-08" ixz="4.1e-07" iyy="0.01077842" iyz="1.896e-05" izz="0.0007042000000000001"/>
    </inertial>
  </link>
  <link name="right_arm_link1">
    <inertial>
      <origin rpy="0 0 0" xyz="0.0 -0.0009699999999999999 -0.015390000000000001"/>
      <mass value="1.6"/>
      <inertia ixx="0.00332981" ixy="1.8920000000000002e-05" ixz="6.9e-07" iyy="0.00339121" iyz="2.9760000000000003e-05" izz="0.0016524"/>
    </inertial>
    <visual>
      <origin rpy="0 0 0" xyz="0 0 0"/>
      <geometry>
        <mesh filename="meshes/visual/right_arm/right_arm_link1/obj/right_arm_link1.obj"/>
      </geometry>
    </visual>
    <collision>
      <origin rpy="0 0 0" xyz="0 0 0"/>
      <geometry>
        <mesh filename="meshes/collision/right_arm/right_arm_link1/convex_hull/right_arm_link1_convex_hull.stl"/>
      </geometry>
    </collision>
  </link>
  <joint name="right_arm_joint1" type="revolute">
    <origin rpy="0 0 -0.523598775598286" xyz="0 0 0"/>
    <parent link="right_arm_base_link"/>
    <child link="right_arm_link1"/>
    <axis xyz="0 0 1"/>
    <limit acceleration="2" effort="60" jerk="12" lower="-3.00432619" upper="3.00432619" velocity="1.5"/>
  </joint>
  <link name="right_arm_link2">
    <inertial>
      <origin rpy="0 0 0" xyz="0.0 -0.09558 0.010150000000000001"/>
      <mass value="1.43"/>
      <inertia ixx="0.01937881" ixy="2.0000000000000002e-07" ixz="1.2e-07" iyy="0.0015791400000000001" iyz="0.00019578" izz="0.018951810000000003"/>
    </inertial>
    <visual>
      <origin rpy="0 0 0" xyz="0 0 0"/>
      <geometry>
        <mesh filename="meshes/visual/right_arm/right_arm_link2/obj/right_arm_link2.obj"/>
      </geometry>
    </visual>
    <collision>
      <origin rpy="0 0 0" xyz="0 0 0"/>
      <geometry>
        <mesh filename="meshes/collision/right_arm/right_arm_link2/convex_hull/right_arm_link2_convex_hull.stl"/>
      </geometry>
    </collision>
  </link>
  <joint name="right_arm_joint2" type="revolute">
    <origin rpy="-1.5707963267949 0 3.14159265358979" xyz="0 0 0"/>
    <parent link="right_arm_link1"/>
    <child link="right_arm_link2"/>
    <axis xyz="0 0 1"/>
    <limit acceleration="2" effort="60" jerk="12" lower="-1.608062789" upper="1.608062789" velocity="1.5"/>
  </joint>
  <link name="right_arm_link3">
    <inertial>
      <origin rpy="0 0 0" xyz="0.0 -0.00088 -0.04936"/>
      <mass value="1.43"/>
      <inertia ixx="0.01187457" ixy="1.5e-07" ixz="8.5e-07" iyy="0.01178759" iyz="0.00010048" izz="0.0013715"/>
    </inertial>
    <visual>
      <origin rpy="0 0 0" xyz="0 0 0"/>
      <geometry>
        <mesh filename="meshes/visual/right_arm/right_arm_link3/obj/right_arm_link3.obj"/>
      </geometry>
    </visual>
    <collision>
      <origin rpy="0 0 0" xyz="0 0 0"/>
      <geometry>
        <mesh filename="meshes/collision/right_arm/right_arm_link3/convex_hull/right_arm_link3_convex_hull.stl"/>
      </geometry>
    </collision>
  </link>
  <joint name="right_arm_joint3" type="revolute">
    <origin rpy="-1.5707963267949 1.04719755119629 -3.14159265358979" xyz="0 -0.35 0"/>
    <parent link="right_arm_link2"/>
    <child link="right_arm_link3"/>
    <axis xyz="0 0 1"/>
    <limit acceleration="2" effort="30" jerk="12" lower="-2.916972222" upper="2.916972222" velocity="1.5"/>
  </joint>
  <link name="right_arm_link4">
    <inertial>
      <origin rpy="0 0 0" xyz="0.0 -0.05614 0.019170000000000003"/>
      <mass value="1.1"/>
      <inertia ixx="0.00701388" ixy="3.2e-07" ixz="1.16e-06" iyy="0.00161854" iyz="0.00033944" izz="0.0065011999999999995"/>
    </inertial>
    <visual>
      <origin rpy="0 0 0" xyz="0 0 0"/>
      <geometry>
        <mesh filename="meshes/visual/right_arm/right_arm_link4/obj/right_arm_link4.obj"/>
      </geometry>
    </visual>
    <collision>
      <origin rpy="0 0 0" xyz="0 0 0"/>
      <geometry>
        <mesh filename="meshes/collision/right_arm/right_arm_link4/convex_hull/right_arm_link4_convex_hull.stl"/>
      </geometry>
    </collision>
  </link>
  <joint name="right_arm_joint4" type="revolute">
    <origin rpy="-1.57079632679459 0 3.14159265358979" xyz="0 0 0"/>
    <parent link="right_arm_link3"/>
    <child link="right_arm_link4"/>
    <axis xyz="0 0 1"/>
    <limit acceleration="2" effort="30" jerk="12" lower="-1.869862177" upper="2.5679938779914944" velocity="1.5"/>
  </joint>
  <link name="right_arm_link5">
    <inertial>
      <origin rpy="0 0 0" xyz="0.00044 0.0016899999999999999 -0.13306"/>
      <mass value="1.15"/>
      <inertia ixx="0.025809930000000002" ixy="1.98e-05" ixz="5.605e-05" iyy="0.02530313" iyz="0.00020931999999999998" izz="0.00115848"/>
    </inertial>
    <visual>
      <origin rpy="0 0 0" xyz="0 0 0"/>
      <geometry>
        <mesh filename="meshes/visual/right_arm/right_arm_link5/obj/right_arm_link5.obj"/>
      </geometry>
    </visual>
    <collision>
      <origin rpy="0 0 0" xyz="0 0 0"/>
      <geometry>
        <mesh filename="meshes/collision/right_arm/right_arm_link5/convex_hull/right_arm_link5_convex_hull.stl"/>
      </geometry>
    </collision>
  </link>
  <joint name="right_arm_joint5" type="revolute">
    <origin rpy="-1.5707963267949 0 3.14159265358979" xyz="0 -0.36 0"/>
    <parent link="right_arm_link4"/>
    <child link="right_arm_link5"/>
    <axis xyz="0 0 1"/>
    <limit acceleration="2" effort="10" jerk="12" lower="-2.916972222" upper="2.916972222" velocity="1.5"/>
  </joint>
  <link name="right_arm_link6">
    <inertial>
      <origin rpy="0 0 0" xyz="-0.00088 0.0072699999999999996 -0.00011999999999999999"/>
      <mass value="0.47"/>
      <inertia ixx="0.00027557" ixy="7.6e-07" ixz="1.44e-06" iyy="0.00028977999999999995" iyz="2.25e-06" izz="0.00029684"/>
    </inertial>
    <visual>
      <origin rpy="0 0 0" xyz="0 0 0"/>
      <geometry>
        <mesh filename="meshes/visual/right_arm/right_arm_link6/obj/right_arm_link6.obj"/>
      </geometry>
    </visual>
    <collision>
      <origin rpy="0 0 0" xyz="0 0 0"/>
      <geometry>
        <mesh filename="meshes/collision/right_arm/right_arm_link6/convex_hull/right_arm_link6_convex_hull.stl"/>
      </geometry>
    </collision>
  </link>
  <joint name="right_arm_joint6" type="revolute">
    <origin rpy="1.5707963267949 1.5707963267949 0" xyz="0 0 0"/>
    <parent link="right_arm_link5"/>
    <child link="right_arm_link6"/>
    <axis xyz="0 0 1"/>
    <limit acceleration="2" effort="10" jerk="12" lower="-0.7353981633974483" upper="0.8226646259971648" velocity="1.5"/>
  </joint>
  <link name="right_arm_link7">
    <inertial>
      <origin rpy="0 0 0" xyz="-0.05751 0.00684 0.011869999999999999"/>
      <mass value="0.8"/>
      <inertia ixx="0.00117613" ixy="0.00033793" ixz="0.0001662" iyy="0.00423935" iyz="8.589999999999999e-06" izz="0.00417642"/>
    </inertial>
    <visual>
      <origin rpy="0 0 0" xyz="0 0 0"/>
      <geometry>
        <mesh filename="meshes/visual/right_arm/right_arm_link7/obj/right_arm_link7.obj"/>
      </geometry>
    </visual>
    <collision>
      <origin rpy="0 0 0" xyz="0 0 0"/>
      <geometry>
        <mesh filename="meshes/collision/right_arm/right_arm_link7/convex_hull/right_arm_link7_convex_hull.stl"/>
      </geometry>
    </collision>
  </link>
  <joint name="right_arm_joint7" type="revolute">
    <origin rpy="-1.5707963267949 0 0" xyz="0 0 0"/>
    <parent link="right_arm_link6"/>
    <child link="right_arm_link7"/>
    <axis xyz="0 0 1"/>
    <limit acceleration="2" effort="10" jerk="12" lower="-1.538202778" upper="1.538202778" velocity="1.5"/>
  </joint>
  <link name="right_arm_end_effector_mount_link">
    <inertial>
      <origin rpy="0 0 0" xyz="0 0 0"/>
      <mass value="0"/>
      <inertia ixx="0" ixy="0" ixz="0" iyy="0" iyz="0" izz="0"/>
    </inertial>
  </link>
  <joint name="right_arm_end_effector_mount_joint" type="fixed">
    <origin rpy="3.14159265358979 0 3.14159265358948" xyz="-0.10926 0 0"/>
    <parent link="right_arm_link7"/>
    <child link="right_arm_end_effector_mount_link"/>
    <axis xyz="0 0 0"/>
  </joint>
  <joint name="left_arm_joint" type="fixed">
    <origin rpy="0 0 0" xyz="0 0 0"/>
    <parent link="torso_left_arm_mount_link"/>
    <child link="left_arm_base_link"/>
  </joint>
  <link name="left_arm_base_link">
    <inertial>
      <origin rpy="0 0 0" xyz="0.0 0.0 -0.10506"/>
      <mass value="0.92"/>
      <inertia ixx="0.01075595" ixy="9e-08" ixz="4.1e-07" iyy="0.01077842" iyz="1.896e-05" izz="0.0007042000000000001"/>
    </inertial>
  </link>
  <link name="left_arm_link1">
    <inertial>
      <origin rpy="0 0 0" xyz="0.0 0.0009699999999999999 -0.015390000000000001"/>
      <mass value="1.6"/>
      <inertia ixx="0.00332981" ixy="1.8920000000000002e-05" ixz="6.9e-07" iyy="0.00339121" iyz="2.9760000000000003e-05" izz="0.0016524"/>
    </inertial>
    <visual>
      <origin rpy="0 0 0" xyz="0 0 0"/>
      <geometry>
        <mesh filename="meshes/visual/left_arm/left_arm_link1/obj/left_arm_link1.obj"/>
      </geometry>
    </visual>
    <collision>
      <origin rpy="0 0 0" xyz="0 0 0"/>
      <geometry>
        <mesh filename="meshes/collision/left_arm/left_arm_link1/convex_hull/left_arm_link1_convex_hull.stl"/>
      </geometry>
    </collision>
  </link>
  <joint name="left_arm_joint1" type="revolute">
    <origin rpy="0 0 0.523598775598286" xyz="0 0 0"/>
    <parent link="left_arm_base_link"/>
    <child link="left_arm_link1"/>
    <axis xyz="0 0 1"/>
    <limit acceleration="2" effort="60" jerk="12" lower="-3.00432619" upper="3.00432619" velocity="1.5"/>
  </joint>
  <link name="left_arm_link2">
    <inertial>
      <origin rpy="0 0 0" xyz="0.0 0.09558 0.010150000000000001"/>
      <mass value="1.43"/>
      <inertia ixx="0.01937881" ixy="2.0000000000000002e-07" ixz="1.2e-07" iyy="0.0015791400000000001" iyz="0.00019578" izz="0.018951810000000003"/>
    </inertial>
    <visual>
      <origin rpy="0 0 0" xyz="0 0 0"/>
      <geometry>
        <mesh filename="meshes/visual/left_arm/left_arm_link2/obj/left_arm_link2.obj"/>
      </geometry>
    </visual>
    <collision>
      <origin rpy="0 0 0" xyz="0 0 0"/>
      <geometry>
        <mesh filename="meshes/collision/left_arm/left_arm_link2/convex_hull/left_arm_link2_convex_hull.stl"/>
      </geometry>
    </collision>
  </link>
  <joint name="left_arm_joint2" type="revolute">
    <origin rpy="1.5707963267949 0 3.14159265358979" xyz="0 0 0"/>
    <parent link="left_arm_link1"/>
    <child link="left_arm_link2"/>
    <axis xyz="0 0 1"/>
    <limit acceleration="2" effort="60" jerk="12" lower="-1.608062789" upper="1.608062789" velocity="1.5"/>
  </joint>
  <link name="left_arm_link3">
    <inertial>
      <origin rpy="0 0 0" xyz="0.0 0.00088 -0.04936"/>
      <mass value="1.43"/>
      <inertia ixx="0.01187457" ixy="1.5e-07" ixz="8.5e-07" iyy="0.01178759" iyz="0.00010048" izz="0.0013715"/>
    </inertial>
    <visual>
      <origin rpy="0 0 0" xyz="0 0 0"/>
      <geometry>
        <mesh filename="meshes/visual/left_arm/left_arm_link3/obj/left_arm_link3.obj"/>
      </geometry>
    </visual>
    <collision>
      <origin rpy="0 0 0" xyz="0 0 0"/>
      <geometry>
        <mesh filename="meshes/collision/left_arm/left_arm_link3/convex_hull/left_arm_link3_convex_hull.stl"/>
      </geometry>
    </collision>
  </link>
  <joint name="left_arm_joint3" type="revolute">
    <origin rpy="1.5707963267949 1.0471975511966 -3.14159265358979" xyz="0 0.35 0"/>
    <parent link="left_arm_link2"/>
    <child link="left_arm_link3"/>
    <axis xyz="0 0 1"/>
    <limit acceleration="2" effort="30" jerk="12" lower="-2.916972222" upper="2.916972222" velocity="1.5"/>
  </joint>
  <link name="left_arm_link4">
    <inertial>
      <origin rpy="0 0 0" xyz="0.0 0.05614 0.019170000000000003"/>
      <mass value="1.1"/>
      <inertia ixx="0.00701388" ixy="3.2e-07" ixz="1.16e-06" iyy="0.00161854" iyz="0.00033944" izz="0.0065011999999999995"/>
    </inertial>
    <visual>
      <origin rpy="0 0 0" xyz="0 0 0"/>
      <geometry>
        <mesh filename="meshes/visual/left_arm/left_arm_link4/obj/left_arm_link4.obj"/>
      </geometry>
    </visual>
    <collision>
      <origin rpy="0 0 0" xyz="0 0 0"/>
      <geometry>
        <mesh filename="meshes/collision/left_arm/left_arm_link4/convex_hull/left_arm_link4_convex_hull.stl"/>
      </geometry>
    </collision>
  </link>
  <joint name="left_arm_joint4" type="revolute">
    <origin rpy="1.5707963267949 0 -3.14159265358979" xyz="0 0 0"/>
    <parent link="left_arm_link3"/>
    <child link="left_arm_link4"/>
    <axis xyz="0 0 1"/>
    <limit acceleration="2" effort="30" jerk="12" lower="-2.5679938779914944" upper="1.869862177" velocity="1.5"/>
  </joint>
  <link name="left_arm_link5">
    <inertial>
      <origin rpy="0 0 0" xyz="0.00044 0.0016899999999999999 -0.13306"/>
      <mass value="1.15"/>
      <inertia ixx="0.025809930000000002" ixy="1.98e-05" ixz="5.605e-05" iyy="0.02530313" iyz="0.00020931999999999998" izz="0.00115848"/>
    </inertial>
    <visual>
      <origin rpy="0 0 0" xyz="0 0 0"/>
      <geometry>
        <mesh filename="meshes/visual/left_arm/left_arm_link5/obj/left_arm_link5.obj"/>
      </geometry>
    </visual>
    <collision>
      <origin rpy="0 0 0" xyz="0 0 0"/>
      <geometry>
        <mesh filename="meshes/collision/left_arm/left_arm_link5/convex_hull/left_arm_link5_convex_hull.stl"/>
      </geometry>
    </collision>
  </link>
  <joint name="left_arm_joint5" type="revolute">
    <origin rpy="-1.5707963267949 0 0" xyz="0 0.36 0"/>
    <parent link="left_arm_link4"/>
    <child link="left_arm_link5"/>
    <axis xyz="0 0 1"/>
    <limit acceleration="2" effort="10" jerk="12" lower="-2.916972222" upper="2.916972222" velocity="1.5"/>
  </joint>
  <link name="left_arm_link6">
    <inertial>
      <origin rpy="0 0 0" xyz="-0.00088 -0.0072699999999999996 -0.00011999999999999999"/>
      <mass value="0.47"/>
      <inertia ixx="0.00027557" ixy="7.900000000000001e-07" ixz="1.48e-06" iyy="0.00028977999999999995" iyz="2.25e-06" izz="0.00029684"/>
    </inertial>
    <visual>
      <origin rpy="0 0 0" xyz="0 0 0"/>
      <geometry>
        <mesh filename="meshes/visual/left_arm/left_arm_link6/obj/left_arm_link6.obj"/>
      </geometry>
    </visual>
    <collision>
      <origin rpy="0 0 0" xyz="0 0 0"/>
      <geometry>
        <mesh filename="meshes/collision/left_arm/left_arm_link6/convex_hull/left_arm_link6_convex_hull.stl"/>
      </geometry>
    </collision>
  </link>
  <joint name="left_arm_joint6" type="revolute">
    <origin rpy="1.5707963267949 1.5707963267949 0" xyz="0 0 0"/>
    <parent link="left_arm_link5"/>
    <child link="left_arm_link6"/>
    <axis xyz="0 0 1"/>
    <limit acceleration="2" effort="10" jerk="12" lower="-0.8226646259971648" upper="0.7353981633974483" velocity="1.5"/>
  </joint>
  <link name="left_arm_link7">
    <inertial>
      <origin rpy="0 0 0" xyz="-0.05776 -0.00675 0.011349999999999999"/>
      <mass value="0.8"/>
      <inertia ixx="0.00116375" ixy="0.00033236" ixz="0.00014869" iyy="0.00424012" iyz="6.570000000000001e-06" izz="0.00418879"/>
    </inertial>
    <visual>
      <origin rpy="0 0 0" xyz="0 0 0"/>
      <geometry>
        <mesh filename="meshes/visual/left_arm/left_arm_link7/obj/left_arm_link7.obj"/>
      </geometry>
    </visual>
    <collision>
      <origin rpy="0 0 0" xyz="0 0 0"/>
      <geometry>
        <mesh filename="meshes/collision/left_arm/left_arm_link7/convex_hull/left_arm_link7_convex_hull.stl"/>
      </geometry>
    </collision>
  </link>
  <joint name="left_arm_joint7" type="revolute">
    <origin rpy="1.5707963267949 0 0" xyz="0 0 0"/>
    <parent link="left_arm_link6"/>
    <child link="left_arm_link7"/>
    <axis xyz="0 0 1"/>
    <limit acceleration="2" effort="10" jerk="12" lower="-1.538202778" upper="1.538202778" velocity="1.5"/>
  </joint>
  <link name="left_arm_end_effector_mount_link">
    <inertial>
      <origin rpy="0 0 0" xyz="0 0 0"/>
      <mass value="0"/>
      <inertia ixx="0" ixy="0" ixz="0" iyy="0" iyz="0" izz="0"/>
    </inertial>
  </link>
  <joint name="left_arm_end_effector_mount_joint" type="fixed">
    <origin rpy="3.14159265358979 0 3.14159265358979" xyz="-0.10926 0 0"/>
    <parent link="left_arm_link7"/>
    <child link="left_arm_end_effector_mount_link"/>
    <axis xyz="0 0 0"/>
  </joint>
  <!-- 使用右侧外指作为驱动关节 -->
  <!-- 固定关节连接父级 -->
  <joint name="right_gripper_joint" type="fixed">
    <origin rpy="1.5707963267948966 0 0" xyz="0 0 0"/>
    <parent link="right_arm_end_effector_mount_link"/>
    <child link="right_gripper_flange_link"/>
  </joint>
  <link name="right_gripper_flange_link">
    <inertial>
      <origin rpy="0 0 0" xyz="0.0030662 -1.4019E-18 3.383E-18"/>
      <mass value="0.031005"/>
      <inertia ixx="2.2585E-05" ixy="-2.0366E-21" ixz="-3.7461E-22" iyy="1.141E-05" iyz="-7.8518E-23" izz="1.141E-05"/>
    </inertial>
    <visual>
      <geometry>
        <mesh filename="meshes/visual/gripper/galbot_gripper1/flange_link.obj"/>
      </geometry>
    </visual>
    <collision>
      <origin rpy="0 0 0" xyz="0 0 0"/>
      <geometry>
        <mesh filename="meshes/collision/gripper/galbot_gripper1/convex_hull/flange_link_convex_hull.stl"/>
      </geometry>
    </collision>
  </link>
  <!-- 新增：基链接固定关节（连接法兰和基链接） -->
  <joint name="right_gripper_base_joint" type="fixed">
    <origin rpy="0 0 0" xyz="0.0065 0 0"/>
    <parent link="right_gripper_flange_link"/>
    <child link="right_gripper_base_link"/>
    <axis xyz="0 0 0"/>
  </joint>
  <!-- 基础连杆 -->
  <link name="right_gripper_base_link">
    <inertial>
      <origin rpy="0 0 0" xyz="0.037051 -6.4001E-05 6.4706E-05"/>
      <mass value="0.061747"/>
      <inertia ixx="2.5813E-05" ixy="4.7224E-08" ixz="-3.9403E-11" iyy="7.2859E-05" iyz="-2.962E-10" izz="5.7173E-05"/>
    </inertial>
    <visual>
      <geometry>
        <mesh filename="meshes/visual/gripper/galbot_gripper1/base_link.obj"/>
      </geometry>
    </visual>
    <collision>
      <origin rpy="0 0 0" xyz="0 0 0"/>
      <geometry>
        <mesh filename="meshes/collision/gripper/galbot_gripper1/convex_hull/base_link_convex_hull.stl"/>
      </geometry>
    </collision>
  </link>
  <!-- 指节 -->
  <link name="right_gripper_l_knuckle_link">
    <inertial>
      <origin rpy="0 0 0" xyz="0.024101 0 0"/>
      <mass value="0.0070682"/>
      <inertia ixx="9.2131e-08" ixy="0" ixz="0" iyy="1.559e-06" iyz="0" izz="1.4931e-06"/>
    </inertial>
    <visual>
      <geometry>
        <mesh filename="meshes/visual/gripper/galbot_gripper1/l_link_1.obj"/>
      </geometry>
    </visual>
    <collision>
      <origin rpy="0 0 0" xyz="0 0 0"/>
      <geometry>
        <mesh filename="meshes/collision/gripper/galbot_gripper1/convex_hull/l_link_1_convex_hull.stl"/>
      </geometry>
    </collision>
  </link>
  <!-- 内指节 -->
  <link name="right_gripper_l_inner_knuckle_link">
    <inertial>
      <origin rpy="0 0 0" xyz="0.023769 0 0"/>
      <mass value="0.007802"/>
      <inertia ixx="1.044e-07" ixy="0" ixz="0" iyy="1.6385e-06" iyz="0" izz="1.566e-06"/>
    </inertial>
    <visual>
      <geometry>
        <mesh filename="meshes/visual/gripper/galbot_gripper1/l_link_2.obj"/>
      </geometry>
    </visual>
    <collision>
      <origin rpy="0 0 0" xyz="0 0 0"/>
      <geometry>
        <mesh filename="meshes/collision/gripper/galbot_gripper1/convex_hull/l_link_2_convex_hull.stl"/>
      </geometry>
    </collision>
  </link>
  <joint name="right_gripper_l_inner_knuckle_joint" type="revolute">
    <parent link="right_gripper_base_link"/>
    <child link="right_gripper_l_inner_knuckle_link"/>
    <origin rpy="1.5707963267948966 1.2465 0" xyz="0.079 0 -0.026"/>
    <axis xyz="0 0 1"/>
    <limit effort="1000" lower="-3.13" upper="3.13" velocity="2.0"/>
    <mimic joint="right_gripper_r_knuckle_joint" multiplier="1"/>
  </joint>
  <!-- 指尖 -->
  <link name="right_gripper_l_finger_link">
    <inertial>
      <origin rpy="0 0 0" xyz="0.016809 0.0019094 0"/>
      <mass value="0.015957"/>
      <inertia ixx="5.5426e-07" ixy="0" ixz="0" iyy="1.8538e-06" iyz="0" izz="1.5262e-06"/>
    </inertial>
    <visual>
      <geometry>
        <mesh filename="meshes/visual/gripper/galbot_gripper1/l_link_3_zhitao.obj"/>
      </geometry>
    </visual>
    <collision>
      <origin rpy="0 0 0" xyz="0 0 0"/>
      <geometry>
        <mesh filename="meshes/collision/gripper/galbot_gripper1/convex_hull/l_link_3_zhitao_convex_hull.stl"/>
      </geometry>
    </collision>
  </link>
  <joint name="right_gripper_l_finger_joint" type="revolute">
    <parent link="right_gripper_l_inner_knuckle_link"/>
    <child link="right_gripper_l_finger_link"/>
    <origin rpy="0 0 1.2465" xyz="0.045 0 0"/>
    <axis xyz="0 0 1"/>
    <limit effort="1000" lower="-3.13" upper="3.13" velocity="2.0"/>
    <mimic joint="right_gripper_r_knuckle_joint" multiplier="-1"/>
  </joint>
  <!-- 指节 -->
  <link name="right_gripper_r_knuckle_link">
    <inertial>
      <origin rpy="0 0 0" xyz="0.024101 0 0"/>
      <mass value="0.0070682"/>
      <inertia ixx="9.2131e-08" ixy="0" ixz="0" iyy="1.559e-06" iyz="0" izz="1.4931e-06"/>
    </inertial>
    <visual>
      <geometry>
        <mesh filename="meshes/visual/gripper/galbot_gripper1/r_link_1.obj"/>
      </geometry>
    </visual>
    <collision>
      <origin rpy="0 0 0" xyz="0 0 0"/>
      <geometry>
        <mesh filename="meshes/collision/gripper/galbot_gripper1/convex_hull/r_link_1_convex_hull.stl"/>
      </geometry>
    </collision>
  </link>
  <!-- 内指节 -->
  <link name="right_gripper_r_inner_knuckle_link">
    <inertial>
      <origin rpy="0 0 0" xyz="0.023769 0 0"/>
      <mass value="0.007802"/>
      <inertia ixx="1.044e-07" ixy="0" ixz="0" iyy="1.6385e-06" iyz="0" izz="1.566e-06"/>
    </inertial>
    <visual>
      <geometry>
        <mesh filename="meshes/visual/gripper/galbot_gripper1/r_link_2.obj"/>
      </geometry>
    </visual>
    <collision>
      <origin rpy="0 0 0" xyz="0 0 0"/>
      <geometry>
        <mesh filename="meshes/collision/gripper/galbot_gripper1/convex_hull/r_link_2_convex_hull.stl"/>
      </geometry>
    </collision>
  </link>
  <joint name="right_gripper_r_inner_knuckle_joint" type="revolute">
    <parent link="right_gripper_base_link"/>
    <child link="right_gripper_r_inner_knuckle_link"/>
    <origin rpy="1.5707963267948966 -1.2465 0" xyz="0.079 0 0.026"/>
    <axis xyz="0 0 1"/>
    <limit effort="1000" lower="-3.13" upper="3.13" velocity="2.0"/>
    <mimic joint="right_gripper_r_knuckle_joint" multiplier="-1"/>
  </joint>
  <!-- 指尖 -->
  <link name="right_gripper_r_finger_link">
    <inertial>
      <origin rpy="0 0 0" xyz="0.016809 -0.0019094 0"/>
      <mass value="0.015957"/>
      <inertia ixx="5.5426e-07" ixy="0" ixz="0" iyy="1.8538e-06" iyz="0" izz="1.5262e-06"/>
    </inertial>
    <visual>
      <geometry>
        <mesh filename="meshes/visual/gripper/galbot_gripper1/r_link_3_zhitao.obj"/>
      </geometry>
    </visual>
    <collision>
      <origin rpy="0 0 0" xyz="0 0 0"/>
      <geometry>
        <mesh filename="meshes/collision/gripper/galbot_gripper1/convex_hull/r_link_3_zhitao_convex_hull.stl"/>
      </geometry>
    </collision>
  </link>
  <joint name="right_gripper_r_finger_joint" type="revolute">
    <parent link="right_gripper_r_inner_knuckle_link"/>
    <child link="right_gripper_r_finger_link"/>
    <origin rpy="0 0 -1.2465" xyz="0.045 0 0"/>
    <axis xyz="0 0 1"/>
    <limit effort="1000" lower="-3.13" upper="3.13" velocity="2.0"/>
    <mimic joint="right_gripper_r_knuckle_joint" multiplier="1"/>
  </joint>
  <!-- 右侧指节关节（主动关节） -->
  <joint name="right_gripper_r_knuckle_joint" type="revolute">
    <parent link="right_gripper_base_link"/>
    <child link="right_gripper_r_knuckle_link"/>
    <origin rpy="1.5707963267948966 -1.2465 0" xyz="0.0745 0 0.0385"/>
    <axis xyz="0 0 -1"/>
    <limit effort="50" lower="0.0" upper="1.703" velocity="0.5"/>
  </joint>
  <!-- 左侧指节关节 -->
  <joint name="right_gripper_l_knuckle_joint" type="revolute">
    <parent link="right_gripper_base_link"/>
    <child link="right_gripper_l_knuckle_link"/>
    <origin rpy="1.5707963267948966 1.2465 0" xyz="0.0745 0 -0.0385"/>
    <axis xyz="0 0 1"/>
    <limit effort="50" lower="-3.13" upper="3.13" velocity="0.5"/>
    <mimic joint="right_gripper_r_knuckle_joint" multiplier="1"/>
  </joint>
  <!-- TCP -->
  <link name="right_gripper_tcp_link"/>
  <joint name="right_gripper_tcp_joint" type="fixed">
    <parent link="right_gripper_base_link"/>
    <child link="right_gripper_tcp_link"/>
    <origin rpy="-1.5707963267948966 0 0" xyz="0.13996 0 0"/>
  </joint>
  <joint name="right_joint" type="fixed">
    <origin rpy="0 0 0" xyz="0 0 0"/>
    <parent link="right_arm_link7"/>
    <child link="right_wrist_camera_link"/>
  </joint>
  <link name="right_wrist_camera_link">
    <inertial>
      <origin rpy="0 0 0" xyz="-0.0621229724155358 -0.0628379837355285 -0.00140310958315455"/>
      <mass value="0.0492751941348016"/>
      <inertia ixx="3.66069470547417E-05" ixy="-3.55284385731841E-07" ixz="3.8533182318026E-07" iyy="3.08593710158624E-05" iyz="-3.07292981503681E-07" izz="8.80145863410975E-06"/>
    </inertial>
    <visual>
      <origin rpy="0 0 0" xyz="0 0 0"/>
      <geometry>
        <mesh filename="meshes/visual/camera/d405_camera/right_wrist_d405_camera/obj/right_wrist_d405_camera.obj"/>
      </geometry>
      <material name="material_right_wrist_d405_camera">
        <color rgba="0.7 0.7 0.7 1.0"/>
      </material>
    </visual>
    <collision>
      <origin rpy="0 0 0" xyz="0 0 0"/>
      <geometry>
        <mesh filename="meshes/collision/camera/d405_camera/right_wrist_d405_camera/convex_decomposition/right_wrist_d405_camera_convex_decomposition_0.stl"/>
      </geometry>
    </collision>
    <collision>
      <origin rpy="0 0 0" xyz="0 0 0"/>
      <geometry>
        <mesh filename="meshes/collision/camera/d405_camera/right_wrist_d405_camera/convex_decomposition/right_wrist_d405_camera_convex_decomposition_1.stl"/>
      </geometry>
    </collision>
    <collision>
      <origin rpy="0 0 0" xyz="0 0 0"/>
      <geometry>
        <mesh filename="meshes/collision/camera/d405_camera/right_wrist_d405_camera/convex_decomposition/right_wrist_d405_camera_convex_decomposition_2.stl"/>
      </geometry>
    </collision>
    <collision>
      <origin rpy="0 0 0" xyz="0 0 0"/>
      <geometry>
        <mesh filename="meshes/collision/camera/d405_camera/right_wrist_d405_camera/convex_decomposition/right_wrist_d405_camera_convex_decomposition_3.stl"/>
      </geometry>
    </collision>
    <collision>
      <origin rpy="0 0 0" xyz="0 0 0"/>
      <geometry>
        <mesh filename="meshes/collision/camera/d405_camera/right_wrist_d405_camera/convex_decomposition/right_wrist_d405_camera_convex_decomposition_4.stl"/>
      </geometry>
    </collision>
  </link>
  <!-- Left Arm End Effector -->
  <joint name="left_suction_cup_joint" type="fixed">
    <origin rpy="-1.5707963267948966 -3.141592653589793 0" xyz="0 0 0"/>
    <parent link="left_arm_end_effector_mount_link"/>
    <child link="left_suction_cup_base_link"/>
  </joint>
  <link name="left_suction_cup_base_link">
    <inertial>
      <origin rpy="0 0 0" xyz="-4.0035E-05 -0.00015919 0.065665"/>
      <mass value="0.36941"/>
      <inertia ixx="0.00014564" ixy="3.5459E-07" ixz="-1.2386E-07" iyy="0.00016918" iyz="-4.0084E-07" izz="0.000219"/>
    </inertial>
    <visual>
      <origin rpy="0 0 0" xyz="0 0 0"/>
      <geometry>
        <mesh filename="meshes/visual/suction_cup/galbot_suction_cup1/suction_cup_base_link/obj/suction_cup_base_link.obj"/>
      </geometry>
    </visual>
    <collision>
      <origin rpy="0 0 0" xyz="0 0 0"/>
      <geometry>
        <mesh filename="meshes/collision/suction_cup/galbot_suction_cup1/suction_cup_base_link/convex_hull/suction_cup_base_link_convex_hull.stl"/>
      </geometry>
    </collision>
  </link>
  <link name="left_suction_cup_link1">
    <inertial>
      <origin rpy="0 0 0" xyz="0.037966 -3.0191E-05 -4.2414E-08"/>
      <mass value="0.063856"/>
      <inertia ixx="7.1717E-06" ixy="1.7711E-08" ixz="-3.6994E-11" iyy="8.0256E-06" iyz="4.7383E-09" izz="7.78E-06"/>
    </inertial>
    <visual>
      <origin rpy="0 0 0" xyz="0 0 0"/>
      <geometry>
        <mesh filename="meshes/visual/suction_cup/galbot_suction_cup1/suction_cup_link1/obj/suction_cup_link1.obj"/>
      </geometry>
    </visual>
    <collision>
      <origin rpy="0 0 0" xyz="0 0 0"/>
      <geometry>
        <mesh filename="meshes/collision/suction_cup/galbot_suction_cup1/suction_cup_link1/convex_hull/suction_cup_link1_convex_hull.stl"/>
      </geometry>
    </collision>
  </link>
  <joint name="left_suction_cup_joint1" type="revolute">
    <origin rpy="0 0 -1.5707963267948966" xyz="-0.1428 0 0"/>
    <parent link="left_suction_cup_base_link"/>
    <child link="left_suction_cup_link1"/>
    <axis xyz="0 0 1"/>
    <limit effort="1" lower="0" upper="1.570796327" velocity="1.570796327"/>
  </joint>
  <link name="left_suction_cup_tcp_link"/>
  <joint name="left_suction_cup_tcp_joint" type="fixed">
    <origin rpy="1.5707963267948966 0 -1.5707963267948966" xyz="0 -0.079807 0"/>
    <parent link="left_suction_cup_link1"/>
    <child link="left_suction_cup_tcp_link"/>
    <axis xyz="0 0 0"/>
  </joint>
  <joint name="left_joint" type="fixed">
    <origin rpy="0 0 0" xyz="0 0 0"/>
    <parent link="left_arm_link7"/>
    <child link="left_wrist_camera_link"/>
  </joint>
  <link name="left_wrist_camera_link">
    <inertial>
      <origin rpy="0 0 0" xyz="-0.0621229724155358 -0.0628379837355285 -0.00140310958315455"/>
      <mass value="0.0492751941348016"/>
      <inertia ixx="3.66069470547417E-05" ixy="-3.55284385731841E-07" ixz="3.8533182318026E-07" iyy="3.08593710158624E-05" iyz="-3.07292981503681E-07" izz="8.80145863410975E-06"/>
    </inertial>
    <visual>
      <origin rpy="0 0 0" xyz="0 0 0"/>
      <geometry>
        <mesh filename="meshes/visual/camera/d415_camera/left_wrist_d415_camera/obj/left_wrist_d415_camera.obj"/>
      </geometry>
    </visual>
    <collision>
      <origin rpy="0 0 0" xyz="0 0 0"/>
      <geometry>
        <mesh filename="meshes/collision/camera/d415_camera/left_wrist_d415_camera/convex_decomposition/left_wrist_d415_camera_convex_decomposition_0.stl"/>
      </geometry>
    </collision>
    <collision>
      <origin rpy="0 0 0" xyz="0 0 0"/>
      <geometry>
        <mesh filename="meshes/collision/camera/d415_camera/left_wrist_d415_camera/convex_decomposition/left_wrist_d415_camera_convex_decomposition_1.stl"/>
      </geometry>
    </collision>
    <collision>
      <origin rpy="0 0 0" xyz="0 0 0"/>
      <geometry>
        <mesh filename="meshes/collision/camera/d415_camera/left_wrist_d415_camera/convex_decomposition/left_wrist_d415_camera_convex_decomposition_2.stl"/>
      </geometry>
    </collision>
    <collision>
      <origin rpy="0 0 0" xyz="0 0 0"/>
      <geometry>
        <mesh filename="meshes/collision/camera/d415_camera/left_wrist_d415_camera/convex_decomposition/left_wrist_d415_camera_convex_decomposition_3.stl"/>
      </geometry>
    </collision>
  </link>
</robot>
